2025-03-22 16:52:31,997 ERROR: Exception on /auth/login [GET] [in /home/roman/IT/my_progs_directory/Python/new_flask_book/venv/lib/python3.12/site-packages/flask/app.py:875]
Traceback (most recent call last):
  File "/home/roman/IT/my_progs_directory/Python/new_flask_book/venv/lib/python3.12/site-packages/flask/app.py", line 1511, in wsgi_app
    response = self.full_dispatch_request()
               ^^^^^^^^^^^^^^^^^^^^^^^^^^^^
  File "/home/roman/IT/my_progs_directory/Python/new_flask_book/venv/lib/python3.12/site-packages/flask/app.py", line 919, in full_dispatch_request
    rv = self.handle_user_exception(e)
         ^^^^^^^^^^^^^^^^^^^^^^^^^^^^^
  File "/home/roman/IT/my_progs_directory/Python/new_flask_book/venv/lib/python3.12/site-packages/flask/app.py", line 917, in full_dispatch_request
    rv = self.dispatch_request()
         ^^^^^^^^^^^^^^^^^^^^^^^
  File "/home/roman/IT/my_progs_directory/Python/new_flask_book/venv/lib/python3.12/site-packages/flask/app.py", line 902, in dispatch_request
    return self.ensure_sync(self.view_functions[rule.endpoint])(**view_args)  # type: ignore[no-any-return]
           ^^^^^^^^^^^^^^^^^^^^^^^^^^^^^^^^^^^^^^^^^^^^^^^^^^^^^^^^^^^^^^^^^
  File "/home/roman/IT/my_progs_directory/Python/new_flask_book/my_app/auth/routes.py", line 30, in login
    return render_template('auth/login.html', title=_('Sign In'), form=form)
           ^^^^^^^^^^^^^^^^^^^^^^^^^^^^^^^^^^^^^^^^^^^^^^^^^^^^^^^^^^^^^^^^^
  File "/home/roman/IT/my_progs_directory/Python/new_flask_book/venv/lib/python3.12/site-packages/flask/templating.py", line 150, in render_template
    return _render(app, template, context)
           ^^^^^^^^^^^^^^^^^^^^^^^^^^^^^^^
  File "/home/roman/IT/my_progs_directory/Python/new_flask_book/venv/lib/python3.12/site-packages/flask/templating.py", line 131, in _render
    rv = template.render(context)
         ^^^^^^^^^^^^^^^^^^^^^^^^
  File "/home/roman/IT/my_progs_directory/Python/new_flask_book/venv/lib/python3.12/site-packages/jinja2/environment.py", line 1295, in render
    self.environment.handle_exception()
  File "/home/roman/IT/my_progs_directory/Python/new_flask_book/venv/lib/python3.12/site-packages/jinja2/environment.py", line 942, in handle_exception
    raise rewrite_traceback_stack(source=source)
  File "/home/roman/IT/my_progs_directory/Python/new_flask_book/my_app/templates/auth/login.html", line 2, in top-level template code
    {% import "bootstrap_wtf.html" as wtf %}
    ^^^^^^^^^^^^^^^^^^^^^^^^^
  File "/home/roman/IT/my_progs_directory/Python/new_flask_book/my_app/templates/base.html", line 58, in top-level template code
    {% block content %}{% endblock %}
    ^^^^^^^^^^^^^^^^^^^^^^^^^
  File "/home/roman/IT/my_progs_directory/Python/new_flask_book/my_app/templates/auth/login.html", line 7, in block 'content'
    <p>{{ _('New User?') }} <a href="{{ url_for('register') }}">{{ _('Click to Register!') }}</a></p>
    ^^^^^^^^^^^^^^^^^^^^^^^^^
  File "/home/roman/IT/my_progs_directory/Python/new_flask_book/venv/lib/python3.12/site-packages/flask/app.py", line 1121, in url_for
    return self.handle_url_build_error(error, endpoint, values)
           ^^^^^^^^^^^^^^^^^^^^^^^^^^^^^^^^^^^^^^^^^^^^^^^^^^^^
  File "/home/roman/IT/my_progs_directory/Python/new_flask_book/venv/lib/python3.12/site-packages/flask/app.py", line 1110, in url_for
    rv = url_adapter.build(  # type: ignore[union-attr]
         ^^^^^^^^^^^^^^^^^^^^^^^^^^^^^^^^^^^^^^^^^^^^^^
  File "/home/roman/IT/my_progs_directory/Python/new_flask_book/venv/lib/python3.12/site-packages/werkzeug/routing/map.py", line 924, in build
    raise BuildError(endpoint, values, method, self)
werkzeug.routing.exceptions.BuildError: Could not build url for endpoint 'register'. Did you mean 'auth.register' instead?
2025-03-22 16:54:23,804 INFO: Microblog startup [in /home/roman/IT/my_progs_directory/Python/new_flask_book/my_app/__init__.py:82]
2025-03-22 16:54:26,010 ERROR: Exception on /auth/login [GET] [in /home/roman/IT/my_progs_directory/Python/new_flask_book/venv/lib/python3.12/site-packages/flask/app.py:875]
Traceback (most recent call last):
  File "/home/roman/IT/my_progs_directory/Python/new_flask_book/venv/lib/python3.12/site-packages/flask/app.py", line 1511, in wsgi_app
    response = self.full_dispatch_request()
               ^^^^^^^^^^^^^^^^^^^^^^^^^^^^
  File "/home/roman/IT/my_progs_directory/Python/new_flask_book/venv/lib/python3.12/site-packages/flask/app.py", line 919, in full_dispatch_request
    rv = self.handle_user_exception(e)
         ^^^^^^^^^^^^^^^^^^^^^^^^^^^^^
  File "/home/roman/IT/my_progs_directory/Python/new_flask_book/venv/lib/python3.12/site-packages/flask/app.py", line 917, in full_dispatch_request
    rv = self.dispatch_request()
         ^^^^^^^^^^^^^^^^^^^^^^^
  File "/home/roman/IT/my_progs_directory/Python/new_flask_book/venv/lib/python3.12/site-packages/flask/app.py", line 902, in dispatch_request
    return self.ensure_sync(self.view_functions[rule.endpoint])(**view_args)  # type: ignore[no-any-return]
           ^^^^^^^^^^^^^^^^^^^^^^^^^^^^^^^^^^^^^^^^^^^^^^^^^^^^^^^^^^^^^^^^^
  File "/home/roman/IT/my_progs_directory/Python/new_flask_book/my_app/auth/routes.py", line 30, in login
    return render_template('auth/login.html', title=_('Sign In'), form=form)
           ^^^^^^^^^^^^^^^^^^^^^^^^^^^^^^^^^^^^^^^^^^^^^^^^^^^^^^^^^^^^^^^^^
  File "/home/roman/IT/my_progs_directory/Python/new_flask_book/venv/lib/python3.12/site-packages/flask/templating.py", line 150, in render_template
    return _render(app, template, context)
           ^^^^^^^^^^^^^^^^^^^^^^^^^^^^^^^
  File "/home/roman/IT/my_progs_directory/Python/new_flask_book/venv/lib/python3.12/site-packages/flask/templating.py", line 131, in _render
    rv = template.render(context)
         ^^^^^^^^^^^^^^^^^^^^^^^^
  File "/home/roman/IT/my_progs_directory/Python/new_flask_book/venv/lib/python3.12/site-packages/jinja2/environment.py", line 1295, in render
    self.environment.handle_exception()
  File "/home/roman/IT/my_progs_directory/Python/new_flask_book/venv/lib/python3.12/site-packages/jinja2/environment.py", line 942, in handle_exception
    raise rewrite_traceback_stack(source=source)
  File "/home/roman/IT/my_progs_directory/Python/new_flask_book/my_app/templates/auth/login.html", line 2, in top-level template code
    {% import "bootstrap_wtf.html" as wtf %}
    ^^^^^^^^^^^^^^^^^^^^^^^^^
  File "/home/roman/IT/my_progs_directory/Python/new_flask_book/my_app/templates/base.html", line 58, in top-level template code
    {% block content %}{% endblock %}
    ^^^^^^^^^^^^^^^^^^^^^^^^^
  File "/home/roman/IT/my_progs_directory/Python/new_flask_book/my_app/templates/auth/login.html", line 7, in block 'content'
    <p>{{ _('New User?') }} <a href="{{ url_for('register') }}">{{ _('Click to Register!') }}</a></p>
    ^^^^^^^^^^^^^^^^^^^^^^^^^
  File "/home/roman/IT/my_progs_directory/Python/new_flask_book/venv/lib/python3.12/site-packages/flask/app.py", line 1121, in url_for
    return self.handle_url_build_error(error, endpoint, values)
           ^^^^^^^^^^^^^^^^^^^^^^^^^^^^^^^^^^^^^^^^^^^^^^^^^^^^
  File "/home/roman/IT/my_progs_directory/Python/new_flask_book/venv/lib/python3.12/site-packages/flask/app.py", line 1110, in url_for
    rv = url_adapter.build(  # type: ignore[union-attr]
         ^^^^^^^^^^^^^^^^^^^^^^^^^^^^^^^^^^^^^^^^^^^^^^
  File "/home/roman/IT/my_progs_directory/Python/new_flask_book/venv/lib/python3.12/site-packages/werkzeug/routing/map.py", line 924, in build
    raise BuildError(endpoint, values, method, self)
werkzeug.routing.exceptions.BuildError: Could not build url for endpoint 'register'. Did you mean 'auth.register' instead?
