2025-03-22 16:54:40,561 ERROR: Exception on /auth/login [GET] [in /home/roman/IT/my_progs_directory/Python/new_flask_book/venv/lib/python3.12/site-packages/flask/app.py:875]
Traceback (most recent call last):
  File "/home/roman/IT/my_progs_directory/Python/new_flask_book/venv/lib/python3.12/site-packages/flask/app.py", line 1511, in wsgi_app
    response = self.full_dispatch_request()
               ^^^^^^^^^^^^^^^^^^^^^^^^^^^^
  File "/home/roman/IT/my_progs_directory/Python/new_flask_book/venv/lib/python3.12/site-packages/flask/app.py", line 919, in full_dispatch_request
    rv = self.handle_user_exception(e)
         ^^^^^^^^^^^^^^^^^^^^^^^^^^^^^
  File "/home/roman/IT/my_progs_directory/Python/new_flask_book/venv/lib/python3.12/site-packages/flask/app.py", line 917, in full_dispatch_request
    rv = self.dispatch_request()
         ^^^^^^^^^^^^^^^^^^^^^^^
  File "/home/roman/IT/my_progs_directory/Python/new_flask_book/venv/lib/python3.12/site-packages/flask/app.py", line 902, in dispatch_request
    return self.ensure_sync(self.view_functions[rule.endpoint])(**view_args)  # type: ignore[no-any-return]
           ^^^^^^^^^^^^^^^^^^^^^^^^^^^^^^^^^^^^^^^^^^^^^^^^^^^^^^^^^^^^^^^^^
  File "/home/roman/IT/my_progs_directory/Python/new_flask_book/my_app/auth/routes.py", line 30, in login
    return render_template('auth/login.html', title=_('Sign In'), form=form)
           ^^^^^^^^^^^^^^^^^^^^^^^^^^^^^^^^^^^^^^^^^^^^^^^^^^^^^^^^^^^^^^^^^
  File "/home/roman/IT/my_progs_directory/Python/new_flask_book/venv/lib/python3.12/site-packages/flask/templating.py", line 150, in render_template
    return _render(app, template, context)
           ^^^^^^^^^^^^^^^^^^^^^^^^^^^^^^^
  File "/home/roman/IT/my_progs_directory/Python/new_flask_book/venv/lib/python3.12/site-packages/flask/templating.py", line 131, in _render
    rv = template.render(context)
         ^^^^^^^^^^^^^^^^^^^^^^^^
  File "/home/roman/IT/my_progs_directory/Python/new_flask_book/venv/lib/python3.12/site-packages/jinja2/environment.py", line 1295, in render
    self.environment.handle_exception()
  File "/home/roman/IT/my_progs_directory/Python/new_flask_book/venv/lib/python3.12/site-packages/jinja2/environment.py", line 942, in handle_exception
    raise rewrite_traceback_stack(source=source)
  File "/home/roman/IT/my_progs_directory/Python/new_flask_book/my_app/templates/auth/login.html", line 2, in top-level template code
    {% import "bootstrap_wtf.html" as wtf %}
    ^^^^^^^^^^^^^^^^^^^^^^^^^
  File "/home/roman/IT/my_progs_directory/Python/new_flask_book/my_app/templates/base.html", line 58, in top-level template code
    {% block content %}{% endblock %}
    ^^^^^^^^^^^^^^^^^^^^^^^^^
  File "/home/roman/IT/my_progs_directory/Python/new_flask_book/my_app/templates/auth/login.html", line 7, in block 'content'
    <p>{{ _('New User?') }} <a href="{{ url_for('register') }}">{{ _('Click to Register!') }}</a></p>
    ^^^^^^^^^^^^^^^^^^^^^^^^^
  File "/home/roman/IT/my_progs_directory/Python/new_flask_book/venv/lib/python3.12/site-packages/flask/app.py", line 1121, in url_for
    return self.handle_url_build_error(error, endpoint, values)
           ^^^^^^^^^^^^^^^^^^^^^^^^^^^^^^^^^^^^^^^^^^^^^^^^^^^^
  File "/home/roman/IT/my_progs_directory/Python/new_flask_book/venv/lib/python3.12/site-packages/flask/app.py", line 1110, in url_for
    rv = url_adapter.build(  # type: ignore[union-attr]
         ^^^^^^^^^^^^^^^^^^^^^^^^^^^^^^^^^^^^^^^^^^^^^^
  File "/home/roman/IT/my_progs_directory/Python/new_flask_book/venv/lib/python3.12/site-packages/werkzeug/routing/map.py", line 924, in build
    raise BuildError(endpoint, values, method, self)
werkzeug.routing.exceptions.BuildError: Could not build url for endpoint 'register'. Did you mean 'auth.register' instead?
2025-03-22 16:56:21,028 INFO: Microblog startup [in /home/roman/IT/my_progs_directory/Python/new_flask_book/my_app/__init__.py:82]
2025-03-22 16:57:37,118 INFO: Microblog startup [in /home/roman/IT/my_progs_directory/Python/new_flask_book/my_app/__init__.py:82]
2025-03-22 16:58:33,984 ERROR: Exception on /index [POST] [in /home/roman/IT/my_progs_directory/Python/new_flask_book/venv/lib/python3.12/site-packages/flask/app.py:875]
Traceback (most recent call last):
  File "/home/roman/IT/my_progs_directory/Python/new_flask_book/venv/lib/python3.12/site-packages/flask/app.py", line 1511, in wsgi_app
    response = self.full_dispatch_request()
               ^^^^^^^^^^^^^^^^^^^^^^^^^^^^
  File "/home/roman/IT/my_progs_directory/Python/new_flask_book/venv/lib/python3.12/site-packages/flask/app.py", line 919, in full_dispatch_request
    rv = self.handle_user_exception(e)
         ^^^^^^^^^^^^^^^^^^^^^^^^^^^^^
  File "/home/roman/IT/my_progs_directory/Python/new_flask_book/venv/lib/python3.12/site-packages/flask/app.py", line 917, in full_dispatch_request
    rv = self.dispatch_request()
         ^^^^^^^^^^^^^^^^^^^^^^^
  File "/home/roman/IT/my_progs_directory/Python/new_flask_book/venv/lib/python3.12/site-packages/flask/app.py", line 902, in dispatch_request
    return self.ensure_sync(self.view_functions[rule.endpoint])(**view_args)  # type: ignore[no-any-return]
           ^^^^^^^^^^^^^^^^^^^^^^^^^^^^^^^^^^^^^^^^^^^^^^^^^^^^^^^^^^^^^^^^^
  File "/home/roman/IT/my_progs_directory/Python/new_flask_book/venv/lib/python3.12/site-packages/flask_login/utils.py", line 290, in decorated_view
    return current_app.ensure_sync(func)(*args, **kwargs)
           ^^^^^^^^^^^^^^^^^^^^^^^^^^^^^^^^^^^^^^^^^^^^^^
  File "/home/roman/IT/my_progs_directory/Python/new_flask_book/my_app/main/routes.py", line 33, in index
    post = Post(body=form.post.data, author=current_user,
           ^^^^^^^^^^^^^^^^^^^^^^^^^^^^^^^^^^^^^^^^^^^^^^
  File "<string>", line 4, in __init__
  File "/home/roman/IT/my_progs_directory/Python/new_flask_book/venv/lib/python3.12/site-packages/sqlalchemy/orm/state.py", line 571, in _initialize_instance
    with util.safe_reraise():
  File "/home/roman/IT/my_progs_directory/Python/new_flask_book/venv/lib/python3.12/site-packages/sqlalchemy/util/langhelpers.py", line 146, in __exit__
    raise exc_value.with_traceback(exc_tb)
  File "/home/roman/IT/my_progs_directory/Python/new_flask_book/venv/lib/python3.12/site-packages/sqlalchemy/orm/state.py", line 569, in _initialize_instance
    manager.original_init(*mixed[1:], **kwargs)
  File "/home/roman/IT/my_progs_directory/Python/new_flask_book/venv/lib/python3.12/site-packages/sqlalchemy/orm/decl_base.py", line 2175, in _declarative_constructor
    raise TypeError(
TypeError: 'language' is an invalid keyword argument for Post
2025-03-22 17:14:28,101 INFO: Microblog startup [in /home/roman/IT/my_progs_directory/Python/new_flask_book/my_app/__init__.py:82]
2025-03-22 17:14:31,657 ERROR: Exception on /index [POST] [in /home/roman/IT/my_progs_directory/Python/new_flask_book/venv/lib/python3.12/site-packages/flask/app.py:875]
Traceback (most recent call last):
  File "/home/roman/IT/my_progs_directory/Python/new_flask_book/venv/lib/python3.12/site-packages/flask/app.py", line 1511, in wsgi_app
    response = self.full_dispatch_request()
               ^^^^^^^^^^^^^^^^^^^^^^^^^^^^
  File "/home/roman/IT/my_progs_directory/Python/new_flask_book/venv/lib/python3.12/site-packages/flask/app.py", line 919, in full_dispatch_request
    rv = self.handle_user_exception(e)
         ^^^^^^^^^^^^^^^^^^^^^^^^^^^^^
  File "/home/roman/IT/my_progs_directory/Python/new_flask_book/venv/lib/python3.12/site-packages/flask/app.py", line 917, in full_dispatch_request
    rv = self.dispatch_request()
         ^^^^^^^^^^^^^^^^^^^^^^^
  File "/home/roman/IT/my_progs_directory/Python/new_flask_book/venv/lib/python3.12/site-packages/flask/app.py", line 902, in dispatch_request
    return self.ensure_sync(self.view_functions[rule.endpoint])(**view_args)  # type: ignore[no-any-return]
           ^^^^^^^^^^^^^^^^^^^^^^^^^^^^^^^^^^^^^^^^^^^^^^^^^^^^^^^^^^^^^^^^^
  File "/home/roman/IT/my_progs_directory/Python/new_flask_book/venv/lib/python3.12/site-packages/flask_login/utils.py", line 290, in decorated_view
    return current_app.ensure_sync(func)(*args, **kwargs)
           ^^^^^^^^^^^^^^^^^^^^^^^^^^^^^^^^^^^^^^^^^^^^^^
  File "/home/roman/IT/my_progs_directory/Python/new_flask_book/my_app/main/routes.py", line 33, in index
    post = Post(body=form.post.data, author=current_user,
           ^^^^^^^^^^^^^^^^^^^^^^^^^^^^^^^^^^^^^^^^^^^^^^
  File "<string>", line 4, in __init__
  File "/home/roman/IT/my_progs_directory/Python/new_flask_book/venv/lib/python3.12/site-packages/sqlalchemy/orm/state.py", line 571, in _initialize_instance
    with util.safe_reraise():
  File "/home/roman/IT/my_progs_directory/Python/new_flask_book/venv/lib/python3.12/site-packages/sqlalchemy/util/langhelpers.py", line 146, in __exit__
    raise exc_value.with_traceback(exc_tb)
  File "/home/roman/IT/my_progs_directory/Python/new_flask_book/venv/lib/python3.12/site-packages/sqlalchemy/orm/state.py", line 569, in _initialize_instance
    manager.original_init(*mixed[1:], **kwargs)
  File "/home/roman/IT/my_progs_directory/Python/new_flask_book/venv/lib/python3.12/site-packages/sqlalchemy/orm/decl_base.py", line 2175, in _declarative_constructor
    raise TypeError(
TypeError: 'language' is an invalid keyword argument for Post
2025-03-22 17:14:57,484 INFO: Microblog startup [in /home/roman/IT/my_progs_directory/Python/new_flask_book/my_app/__init__.py:82]
2025-03-22 17:17:06,501 INFO: Microblog startup [in /home/roman/IT/my_progs_directory/Python/new_flask_book/my_app/__init__.py:82]
2025-03-22 17:18:20,039 INFO: Microblog startup [in /home/roman/IT/my_progs_directory/Python/new_flask_book/my_app/__init__.py:82]
2025-03-22 17:18:30,737 INFO: Microblog startup [in /home/roman/IT/my_progs_directory/Python/new_flask_book/my_app/__init__.py:82]
2025-03-22 17:30:24,529 INFO: Microblog startup [in /home/roman/IT/my_progs_directory/Python/new_flask_book/my_app/__init__.py:82]
2025-03-22 17:42:59,827 INFO: Microblog startup [in /home/roman/IT/my_progs_directory/Python/new_flask_book/my_app/__init__.py:82]
2025-03-22 18:47:37,979 INFO: Microblog startup [in /home/roman/IT/my_progs_directory/Python/new_flask_book/my_app/__init__.py:82]
