2025-03-21 15:32:43,508 INFO: Microblog startup [in /home/roman/IT/my_progs_directory/Python/new_flask_book/my_app/__init__.py:33]
2025-03-21 15:33:14,302 INFO: Microblog startup [in /home/roman/IT/my_progs_directory/Python/new_flask_book/my_app/__init__.py:33]
2025-03-21 15:36:02,756 INFO: Microblog startup [in /home/roman/IT/my_progs_directory/Python/new_flask_book/my_app/__init__.py:33]
2025-03-21 15:36:36,932 INFO: Microblog startup [in /home/roman/IT/my_progs_directory/Python/new_flask_book/my_app/__init__.py:33]
2025-03-21 15:38:30,664 INFO: Microblog startup [in /home/roman/IT/my_progs_directory/Python/new_flask_book/my_app/__init__.py:33]
2025-03-21 15:40:39,502 INFO: Microblog startup [in /home/roman/IT/my_progs_directory/Python/new_flask_book/my_app/__init__.py:33]
2025-03-21 21:06:22,604 INFO: Microblog startup [in /home/roman/IT/my_progs_directory/Python/new_flask_book/my_app/__init__.py:42]
2025-03-21 21:06:36,270 INFO: Microblog startup [in /home/roman/IT/my_progs_directory/Python/new_flask_book/my_app/__init__.py:42]
2025-03-21 21:06:38,823 ERROR: Exception on / [GET] [in /home/roman/IT/my_progs_directory/Python/new_flask_book/venv/lib/python3.12/site-packages/flask/app.py:875]
Traceback (most recent call last):
  File "/home/roman/IT/my_progs_directory/Python/new_flask_book/venv/lib/python3.12/site-packages/flask/app.py", line 1511, in wsgi_app
    response = self.full_dispatch_request()
               ^^^^^^^^^^^^^^^^^^^^^^^^^^^^
  File "/home/roman/IT/my_progs_directory/Python/new_flask_book/venv/lib/python3.12/site-packages/flask/app.py", line 919, in full_dispatch_request
    rv = self.handle_user_exception(e)
         ^^^^^^^^^^^^^^^^^^^^^^^^^^^^^
  File "/home/roman/IT/my_progs_directory/Python/new_flask_book/venv/lib/python3.12/site-packages/flask/app.py", line 915, in full_dispatch_request
    rv = self.preprocess_request()
         ^^^^^^^^^^^^^^^^^^^^^^^^^
  File "/home/roman/IT/my_progs_directory/Python/new_flask_book/venv/lib/python3.12/site-packages/flask/app.py", line 1291, in preprocess_request
    rv = self.ensure_sync(before_func)()
         ^^^^^^^^^^^^^^^^^^^^^^^^^^^^^^^
  File "/home/roman/IT/my_progs_directory/Python/new_flask_book/my_app/routes.py", line 18, in before_request
    g.locale = str(get_locale())
                   ^^^^^^^^^^^^
  File "/home/roman/IT/my_progs_directory/Python/new_flask_book/venv/lib/python3.12/site-packages/flask_babel/__init__.py", line 263, in get_locale
    rv = babel.locale_selector()
         ^^^^^^^^^^^^^^^^^^^^^^^
  File "/home/roman/IT/my_progs_directory/Python/new_flask_book/my_app/__init__.py", line 17, in get_locale
    return request.accept_longuages.best_match(my_app.config['LANGUAGES'])
           ^^^^^^^^^^^^^^^^^^^^^^^^
AttributeError: 'Request' object has no attribute 'accept_longuages'. Did you mean: 'accept_languages'?
2025-03-21 21:07:05,199 INFO: Microblog startup [in /home/roman/IT/my_progs_directory/Python/new_flask_book/my_app/__init__.py:42]
2025-03-21 21:07:06,981 ERROR: Exception on / [GET] [in /home/roman/IT/my_progs_directory/Python/new_flask_book/venv/lib/python3.12/site-packages/flask/app.py:875]
Traceback (most recent call last):
  File "/home/roman/IT/my_progs_directory/Python/new_flask_book/venv/lib/python3.12/site-packages/flask/app.py", line 1511, in wsgi_app
    response = self.full_dispatch_request()
               ^^^^^^^^^^^^^^^^^^^^^^^^^^^^
  File "/home/roman/IT/my_progs_directory/Python/new_flask_book/venv/lib/python3.12/site-packages/flask/app.py", line 919, in full_dispatch_request
    rv = self.handle_user_exception(e)
         ^^^^^^^^^^^^^^^^^^^^^^^^^^^^^
  File "/home/roman/IT/my_progs_directory/Python/new_flask_book/venv/lib/python3.12/site-packages/flask/app.py", line 915, in full_dispatch_request
    rv = self.preprocess_request()
         ^^^^^^^^^^^^^^^^^^^^^^^^^
  File "/home/roman/IT/my_progs_directory/Python/new_flask_book/venv/lib/python3.12/site-packages/flask/app.py", line 1291, in preprocess_request
    rv = self.ensure_sync(before_func)()
         ^^^^^^^^^^^^^^^^^^^^^^^^^^^^^^^
  File "/home/roman/IT/my_progs_directory/Python/new_flask_book/my_app/routes.py", line 18, in before_request
    g.locale = str(get_locale())
                   ^^^^^^^^^^^^
  File "/home/roman/IT/my_progs_directory/Python/new_flask_book/venv/lib/python3.12/site-packages/flask_babel/__init__.py", line 263, in get_locale
    rv = babel.locale_selector()
         ^^^^^^^^^^^^^^^^^^^^^^^
  File "/home/roman/IT/my_progs_directory/Python/new_flask_book/my_app/__init__.py", line 17, in get_locale
    return request.accept_languages.best_match(my_app.config['LANGUAGES'])
                                               ^^^^^^
NameError: name 'my_app' is not defined
2025-03-21 21:07:21,630 INFO: Microblog startup [in /home/roman/IT/my_progs_directory/Python/new_flask_book/my_app/__init__.py:42]
2025-03-21 21:08:09,684 INFO: Microblog startup [in /home/roman/IT/my_progs_directory/Python/new_flask_book/my_app/__init__.py:42]
2025-03-21 21:10:05,940 INFO: Microblog startup [in /home/roman/IT/my_progs_directory/Python/new_flask_book/my_app/__init__.py:42]
2025-03-21 21:10:37,487 INFO: Microblog startup [in /home/roman/IT/my_progs_directory/Python/new_flask_book/my_app/__init__.py:42]
2025-03-21 21:10:46,274 INFO: Microblog startup [in /home/roman/IT/my_progs_directory/Python/new_flask_book/my_app/__init__.py:42]
2025-03-21 21:10:53,645 INFO: Microblog startup [in /home/roman/IT/my_progs_directory/Python/new_flask_book/my_app/__init__.py:42]
2025-03-21 21:10:59,841 INFO: Microblog startup [in /home/roman/IT/my_progs_directory/Python/new_flask_book/my_app/__init__.py:42]
2025-03-21 21:13:14,346 INFO: Microblog startup [in /home/roman/IT/my_progs_directory/Python/new_flask_book/my_app/__init__.py:42]
2025-03-21 21:13:17,612 ERROR: Exception on /profile/Kenzie [GET] [in /home/roman/IT/my_progs_directory/Python/new_flask_book/venv/lib/python3.12/site-packages/flask/app.py:875]
Traceback (most recent call last):
  File "/home/roman/IT/my_progs_directory/Python/new_flask_book/venv/lib/python3.12/site-packages/flask/app.py", line 1511, in wsgi_app
    response = self.full_dispatch_request()
               ^^^^^^^^^^^^^^^^^^^^^^^^^^^^
  File "/home/roman/IT/my_progs_directory/Python/new_flask_book/venv/lib/python3.12/site-packages/flask/app.py", line 919, in full_dispatch_request
    rv = self.handle_user_exception(e)
         ^^^^^^^^^^^^^^^^^^^^^^^^^^^^^
  File "/home/roman/IT/my_progs_directory/Python/new_flask_book/venv/lib/python3.12/site-packages/flask/app.py", line 917, in full_dispatch_request
    rv = self.dispatch_request()
         ^^^^^^^^^^^^^^^^^^^^^^^
  File "/home/roman/IT/my_progs_directory/Python/new_flask_book/venv/lib/python3.12/site-packages/flask/app.py", line 902, in dispatch_request
    return self.ensure_sync(self.view_functions[rule.endpoint])(**view_args)  # type: ignore[no-any-return]
           ^^^^^^^^^^^^^^^^^^^^^^^^^^^^^^^^^^^^^^^^^^^^^^^^^^^^^^^^^^^^^^^^^
  File "/home/roman/IT/my_progs_directory/Python/new_flask_book/venv/lib/python3.12/site-packages/flask_login/utils.py", line 290, in decorated_view
    return current_app.ensure_sync(func)(*args, **kwargs)
           ^^^^^^^^^^^^^^^^^^^^^^^^^^^^^^^^^^^^^^^^^^^^^^
  File "/home/roman/IT/my_progs_directory/Python/new_flask_book/my_app/routes.py", line 135, in user
    return render_template('user.html', user = user, posts = posts.items, form=form, next_url=next_url, prev_url=prev_url)
           ^^^^^^^^^^^^^^^^^^^^^^^^^^^^^^^^^^^^^^^^^^^^^^^^^^^^^^^^^^^^^^^^^^^^^^^^^^^^^^^^^^^^^^^^^^^^^^^^^^^^^^^^^^^^^^^
  File "/home/roman/IT/my_progs_directory/Python/new_flask_book/venv/lib/python3.12/site-packages/flask/templating.py", line 149, in render_template
    template = app.jinja_env.get_or_select_template(template_name_or_list)
               ^^^^^^^^^^^^^^^^^^^^^^^^^^^^^^^^^^^^^^^^^^^^^^^^^^^^^^^^^^^
  File "/home/roman/IT/my_progs_directory/Python/new_flask_book/venv/lib/python3.12/site-packages/jinja2/environment.py", line 1087, in get_or_select_template
    return self.get_template(template_name_or_list, parent, globals)
           ^^^^^^^^^^^^^^^^^^^^^^^^^^^^^^^^^^^^^^^^^^^^^^^^^^^^^^^^^
  File "/home/roman/IT/my_progs_directory/Python/new_flask_book/venv/lib/python3.12/site-packages/jinja2/environment.py", line 1016, in get_template
    return self._load_template(name, globals)
           ^^^^^^^^^^^^^^^^^^^^^^^^^^^^^^^^^^
  File "/home/roman/IT/my_progs_directory/Python/new_flask_book/venv/lib/python3.12/site-packages/jinja2/environment.py", line 975, in _load_template
    template = self.loader.load(self, name, self.make_globals(globals))
               ^^^^^^^^^^^^^^^^^^^^^^^^^^^^^^^^^^^^^^^^^^^^^^^^^^^^^^^^
  File "/home/roman/IT/my_progs_directory/Python/new_flask_book/venv/lib/python3.12/site-packages/jinja2/loaders.py", line 138, in load
    code = environment.compile(source, name, filename)
           ^^^^^^^^^^^^^^^^^^^^^^^^^^^^^^^^^^^^^^^^^^^
  File "/home/roman/IT/my_progs_directory/Python/new_flask_book/venv/lib/python3.12/site-packages/jinja2/environment.py", line 771, in compile
    self.handle_exception(source=source_hint)
  File "/home/roman/IT/my_progs_directory/Python/new_flask_book/venv/lib/python3.12/site-packages/jinja2/environment.py", line 942, in handle_exception
    raise rewrite_traceback_stack(source=source)
  File "/home/roman/IT/my_progs_directory/Python/new_flask_book/my_app/templates/user.html", line 8, in template
    <h1>{{ _'(User') }}: {{user.username}}</h1>
    ^^^^^^^^^^^^^^^^^^^^^^^^^
jinja2.exceptions.TemplateSyntaxError: expected token 'end of print statement', got 'string'
